Workbook
Name MatchupDataTableNoHeaders: OpponentData!$C$2:$F$402
Name OTSQuery: 'GBG DASHBOARD'!$E$9
Name PlayerAltNames: 'Team Info From Paste'!$F$17:$J$17
Name PlayerMonsDropDown: 'Team Info From Paste'!$C$12:$C$18
Name ReplayLinks: HomePage!$C$14:$C$113
Name PokemonIcons: Icons!$B$2:$C$1203
Name OppTeamQuery: 'GBG DASHBOARD'!$E$2
Name Player2: 'Base Data'!$I$3:$I$102
Name MatchupDataTableWithHeaders: OpponentData!$C$1:$F$402
Name OTSDropDown: 'GBG DASHBOARD'!$A$15:$A$17
Name Paste: HomePage!$G$8
Name LeadComboTable: 'Lead Combo Reporting'!$F$5:$J$20
Name PlayerLeadQuery: 'GBG DASHBOARD'!$E$6
Name ResultsDropdown: 'GBG DASHBOARD'!$A$11:$A$13
Name ResultQuery: 'GBG DASHBOARD'!$E$1
Name GameResults: 'Base Data'!$DW$3:$DW$102
Name OppBackQuery: 'GBG DASHBOARD'!$E$4
Name OppLeadQuery: 'GBG DASHBOARD'!$E$3
Name Player1Pokemon: 'Base Data'!$C$3:$H$102
Name Player1: 'Base Data'!$B$3:$B$102
Name PlayerUsedQuery: 'GBG DASHBOARD'!$E$5
Name OppMonsUsed: 'Base Data'!$CZ$3:$DC$102
Name Results: 'Base Data'!$P$3:$P$102
Name FormFixes: Forms!$A$2:$C$141
Name TypeIcons: Icons!$D$2:$E$20
Name Player2Pokemon: 'Base Data'!$J$3:$O$102
Name PlayerTeraQuery: 'GBG DASHBOARD'!$E$8
Name PlayerLeadTable: 'Lead Combo Reporting'!$A$5:$D$105
Name PlayerBackQuery: 'GBG DASHBOARD'!$E$7

Sheet HomePage
D2: PALKIA Academy Showdown Reporting Spreadsheet - V4.3
C4: Step 1 - File -> Make a copy
C6: Step 2 - Put your Showdown Name(s) Here → | G6: Tacodad
C8: Step 3 - Put your Team Pokepaste Here → | G8: https://pokepast.es/fa94d0fcba3c7d5c
H9: =VLOOKUP('Team Info From Paste'!D2, PokemonIcons, 2, False) -> #REF! | I9: =VLOOKUP('Team Info From Paste'!D3, PokemonIcons, 2, False) -> #REF! | J9: =VLOOKUP('Team Info From Paste'!D4, PokemonIcons, 2, False) -> #REF!
H10: =VLOOKUP('Team Info From Paste'!D5, PokemonIcons, 2, False) -> #REF! | I10: =VLOOKUP('Team Info From Paste'!D6, PokemonIcons, 2, False) -> #REF! | J10: =VLOOKUP('Team Info From Paste'!D7, PokemonIcons, 2, False) -> #REF!
C11: Step 4 - Put your showdown replay links (up to 100 at a time) below!
C13: Game links below | G13: Notes
B14: 1 | C14: https://replay.pokemonshowdown.com/gen9vgc2024regf-2070521419-wij2t1c8a3ua2btvwpmll67vtoyd7z8pw | F14: =IF(COUNTIF(ReplayLinks,C14) > 1, "DUPE", "")
B15: 2 | C15: https://replay.pokemonshowdown.com/gen9vgc2024regf-2070524515-ylqh6t9rxtx57ssjtfpu83jlbp1wj7opw | F15: =IF(COUNTIF(ReplayLinks,C15) > 1, "DUPE", "")
B16: 3 | C16: https://replay.pokemonshowdown.com/gen9vgc2024regf-2070529070-n0bmug1nosncwi659y35lhd31swd1tvpw | F16: =IF(COUNTIF(ReplayLinks,C16) > 1, "DUPE", "")
B17: 4 | C17: https://replay.pokemonshowdown.com/gen9vgc2024regf-2070531987-4qs1znrb8c46bpkqrqbk16u396yg2pypw | F17: =IF(COUNTIF(ReplayLinks,C17) > 1, "DUPE", "")
B18: 5 | F18: =IF(COUNTIF(ReplayLinks,C18) > 1, "DUPE", "")
B19: 6 | F19: =IF(COUNTIF(ReplayLinks,C19) > 1, "DUPE", "")
B20: 7 | F20: =IF(COUNTIF(ReplayLinks,C20) > 1, "DUPE", "")
B21: 8 | F21: =IF(COUNTIF(ReplayLinks,C21) > 1, "DUPE", "")
B22: 9 | F22: =IF(COUNTIF(ReplayLinks,C22) > 1, "DUPE", "")
B23: 10 | F23: =IF(COUNTIF(ReplayLinks,C23) > 1, "DUPE", "")
B24: 11 | F24: =IF(COUNTIF(ReplayLinks,C24) > 1, "DUPE", "")
B25: 12 | F25: =IF(COUNTIF(ReplayLinks,C25) > 1, "DUPE", "")
B26: 13 | F26: =IF(COUNTIF(ReplayLinks,C26) > 1, "DUPE", "")
B27: 14 | F27: =IF(COUNTIF(ReplayLinks,C27) > 1, "DUPE", "")
B28: 15 | F28: =IF(COUNTIF(ReplayLinks,C28) > 1, "DUPE", "")
B29: 16 | F29: =IF(COUNTIF(ReplayLinks,C29) > 1, "DUPE", "")
... B113: 100 | F113: =IF(COUNTIF(ReplayLinks,C113) > 1, "DUPE", "")

Sheet Team Info From Paste
A1: {=TRANSPOSE(TEAMDATAFROMPASTE(Paste))} -> Alcremie-Matcha-Cream | C1: Pokemon | D1: Form Clean | E1: Move Lookup Name | F1: Move | G1: Move | H1: Move | I1: Move | J1: Tera Type | K1: Nickname
A2: Decorate | C2: =TRIM(A1) -> Alcremie-Matcha-Cream | D2: =IFERROR(VLOOKUP(C2, FormFixes, 2, false), C2) -> Alcremie | E2: =IF(ISBLANK(VLOOKUP(C2, FormFixes, 3, false)), C2, IFERROR(VLOOKUP(C2, FormFixes, 3, false), C2)) -> Alcremie | F2: =TRIM(A2) -> Decorate | G2: =TRIM(A3) -> Baby-Doll Eyes | H2: =TRIM(A4) -> Calm Mind | I2: =TRIM(A5) -> Draining Kiss | J2: =A31 -> Fairy | K2: =TRIM(A37) -> Alcremie-Matcha-Cream
A3: Baby-Doll Eyes | C3: =TRIM(A6) -> Weavile | D3: =IFERROR(VLOOKUP(C3, FormFixes, 2, false), C3) -> Weavile | E3: =IF(ISBLANK(VLOOKUP(C3, FormFixes, 3, false)), C3, IFERROR(VLOOKUP(C3, FormFixes, 3, false), C3)) -> Weavile | F3: =TRIM(A7) -> Fake Out | G3: =TRIM(A8) -> Ice Spinner | H3: =TRIM(A9) -> Protect | I3: =TRIM(A10) -> Foul Play | J3: =A32 -> Ice | K3: =TRIM(A38) -> Weavile
A4: Calm Mind | C4: =TRIM(A11) -> Skeledirge | D4: =IFERROR(VLOOKUP(C4, FormFixes, 2, false), C4) -> Skeledirge | E4: =IF(ISBLANK(VLOOKUP(C4, FormFixes, 3, false)), C4, IFERROR(VLOOKUP(C4, FormFixes, 3, false), C4)) -> Skeledirge | F4: =TRIM(A12) -> Torch Song | G4: =TRIM(A13) -> Protect | H4: =TRIM(A14) -> Will-O-Wisp | I4: =TRIM(A15) -> Tera Blast | J4: =A33 -> Grass | K4: =TRIM(A39) -> Skeledirge
A5: Draining Kiss | C5: =TRIM(A16) -> Gholdengo | D5: =IFERROR(VLOOKUP(C5, FormFixes, 2, false), C5) -> Gholdengo | E5: =IF(ISBLANK(VLOOKUP(C5, FormFixes, 3, false)), C5, IFERROR(VLOOKUP(C5, FormFixes, 3, false), C5)) -> Gholdengo | F5: =TRIM(A17) -> Make It Rain | G5: =TRIM(A18) -> Flash Cannon | H5: =TRIM(A19) -> Shadow Ball | I5: =TRIM(A20) -> Power Gem | J5: =A34 -> Steel | K5: =TRIM(A40) -> Gholdengo
A6: Weavile | C6: =TRIM(A21) -> Exeggutor-Alola | D6: =IFERROR(VLOOKUP(C6, FormFixes, 2, false), C6) -> Alolan Exeggutor | E6: =IF(ISBLANK(VLOOKUP(C6, FormFixes, 3, false)), C6, IFERROR(VLOOKUP(C6, FormFixes, 3, false), C6)) -> Exeggutor | F6: =TRIM(A22) -> Energy Ball | G6: =TRIM(A23) -> Draco Meteor | H6: =TRIM(A24) -> Ancient Power | I6: =TRIM(A25) -> Sunny Day | J6: =A35 -> Grass | K6: =TRIM(A41) -> Exeggutor-Alola
A7: Fake Out | C7: =TRIM(A26) -> Salamence | D7: =IFERROR(VLOOKUP(C7, FormFixes, 2, false), C7) -> Salamence | E7: =IF(ISBLANK(VLOOKUP(C7, FormFixes, 3, false)), C7, IFERROR(VLOOKUP(C7, FormFixes, 3, false), C7)) -> Salamence | F7: =TRIM(A27) -> Dragon Dance | G7: =TRIM(A28) -> Protect | H7: =TRIM(A29) -> Dragon Claw | I7: =TRIM(A30) -> Dual Wingbeat | J7: =A36 -> Flying | K7: =TRIM(A42) -> Salamence
A8: Ice Spinner | E8: =IFERROR(VLOOKUP(C8, FormFixes, 3, false), C8)
A9: Protect | E9: =IFERROR(VLOOKUP(C9, FormFixes, 3, false), C9)
A10: Foul Play | E10: =IFERROR(VLOOKUP(C10, FormFixes, 3, false), C10)
A11: Skeledirge
A12: Torch Song | C12: -any-
A13: Protect | C13: {=SORT(C2:C7)} -> Alcremie-Matcha-Cream
A14: Will-O-Wisp | C14: Exeggutor-Alola
A15: Tera Blast | C15: Gholdengo
A16: Gholdengo | C16: Salamence
A17: Make It Rain | C17: Skeledirge | E17: Showdown Names Clean | F17: =TRIM(HomePage!G6) -> Tacodad | G17: =TRIM(HomePage!H6) | H17: =TRIM(HomePage!I6) | I17: =TRIM(HomePage!J6) | J17: =TRIM(HomePage!K6)
A18: Flash Cannon | C18: Weavile
A19: Shadow Ball
A20: Power Gem
A21: Exeggutor-Alola
A22: Energy Ball
A23: Draco Meteor
A24: Ancient Power
A25: Sunny Day
A26: Salamence
A27: Dragon Dance
A28: Protect
A29: Dragon Claw
A30: Dual Wingbeat
... A42: Salamence

Sheet Game By Game
B1: ← Hit the + to filter your games! | AD1: Press the [ - ] to collapse
O2: Player | T2: Opponent
O3: Lead | P3: -any- | T3: Lead | U3: -any-
C4: Result | E4: -any- | F4: Opposing Pokemon | I4: -any- | O4: Back | P4: -any- | T4: Back | U4: -any- | Z4: -any- | AD4: -any-
C5: =IF(HomePage!G8 = "https://pokepast.es/df44831dd6e19bf2", "WARNING: You may have forgotten to upate your Pokepaste on the HomePage", IF(HomePage!G6 = "Bauerdad", "WARNING: You may have forgotten your Showdown Username on the HomePage", "")) | Z5: Terastallize | AD5: OTS? | AE5: ELO
B7: Game | C7: Result | F7: Opposing Team | O7: Your Picks | T7: Their Picks | Z7: You | AB7: Opp | AE7: You | AF7: Opp
B8: ='GBG Filtered'!A2 -> 1 | C8: ='GBG Filtered'!B2 -> Loss | D8: ='GBG Filtered'!C2 -> vs | E8: ='GBG Filtered'!D2 -> DoByG | F8: =IF('GBG Filtered'!E2 <> "", VLOOKUP(IFERROR(VLOOKUP('GBG Filtered'!E2, FormFixes, 2, false), 'GBG Filtered'!E2), PokemonIcons, 2, False), "") -> #REF! | G8: =IF('GBG Filtered'!F2 <> "", VLOOKUP(IFERROR(VLOOKUP('GBG Filtered'!F2, FormFixes, 2, false), 'GBG Filtered'!F2), PokemonIcons, 2, False), "") -> #REF! | H8: =IF('GBG Filtered'!G2 <> "", VLOOKUP(IFERROR(VLOOKUP('GBG Filtered'!G2, FormFixes, 2, false), 'GBG Filtered'!G2), PokemonIcons, 2, False), "") -> #REF! | I8: =IF('GBG Filtered'!H2 <> "", VLOOKUP(IFERROR(VLOOKUP('GBG Filtered'!H2, FormFixes, 2, false), 'GBG Filtered'!H2), PokemonIcons, 2, False), "") -> #REF! | J8: =IF('GBG Filtered'!I2 <> "", VLOOKUP(IFERROR(VLOOKUP('GBG Filtered'!I2, FormFixes, 2, false), 'GBG Filtered'!I2), PokemonIcons, 2, False), "") -> #REF! | K8: =IF('GBG Filtered'!J2 <> "", VLOOKUP(IFERROR(VLOOKUP('GBG Filtered'!J2, FormFixes, 2, false), 'GBG Filtered'!J2), PokemonIcons, 2, False), "") -> #REF! | O8: =IF('GBG Filtered'!N2 <> "", VLOOKUP(IFERROR(VLOOKUP('GBG Filtered'!N2, FormFixes, 2, false), 'GBG Filtered'!N2), PokemonIcons, 2, False), "") -> #REF! | P8: =IF('GBG Filtered'!O2 <> "", VLOOKUP(IFERROR(VLOOKUP('GBG Filtered'!O2, FormFixes, 2, false), 'GBG Filtered'!O2), PokemonIcons, 2, False), "") -> #REF! | Q8: =IF('GBG Filtered'!P2 <> "", VLOOKUP(IFERROR(VLOOKUP('GBG Filtered'!P2, FormFixes, 2, false), 'GBG Filtered'!P2), PokemonIcons, 2, False), "") -> #REF! | R8: =IF('GBG Filtered'!Q2 <> "", VLOOKUP(IFERROR(VLOOKUP('GBG Filtered'!Q2, FormFixes, 2, false), 'GBG Filtered'!Q2), PokemonIcons, 2, False), "") -> #REF! | T8: =IF('GBG Filtered'!S2 <> "", VLOOKUP(IFERROR(VLOOKUP('GBG Filtered'!S2, FormFixes, 2, false), 'GBG Filtered'!S2), PokemonIcons, 2, False), "") -> #REF! | U8: =IF('GBG Filtered'!T2 <> "", VLOOKUP(IFERROR(VLOOKUP('GBG Filtered'!T2, FormFixes, 2, false), 'GBG Filtered'!T2), PokemonIcons, 2, False), "") -> #REF! | V8: =IF('GBG Filtered'!U2 <> "", VLOOKUP(IFERROR(VLOOKUP('GBG Filtered'!U2, FormFixes, 2, false), 'GBG Filtered'!U2), PokemonIcons, 2, False), "") -> #REF! | W8: =IF('GBG Filtered'!V2 <> "", VLOOKUP(IFERROR(VLOOKUP('GBG Filtered'!V2, FormFixes, 2, false), 'GBG Filtered'!V2), PokemonIcons, 2, False), "") -> #REF! | Z8: =IF('GBG Filtered'!Y2 <> "", VLOOKUP(IFERROR(VLOOKUP('GBG Filtered'!Y2, FormFixes, 2, false), 'GBG Filtered'!Y2), PokemonIcons, 2, False), "") -> #REF! | AA8: =IF('GBG Filtered'!Z2 <> "", VLOOKUP('GBG Filtered'!Z2, TypeIcons, 2, False), "") -> #REF! | AB8: =IF('GBG Filtered'!AA2 <> "", VLOOKUP(IFERROR(VLOOKUP('GBG Filtered'!AA2, FormFixes, 2, false), 'GBG Filtered'!AA2), PokemonIcons, 2, False), "") -> #REF! | AC8: =IF('GBG Filtered'!AB2 <> "", VLOOKUP('GBG Filtered'!AB2, TypeIcons, 2, False), "") -> #REF! | AD8: ='GBG Filtered'!AC2 | AE8: ='GBG Filtered'!AD2 -> 1032 -> 1017 | AF8: ='GBG Filtered'!AE2 -> 1037
B9: ='GBG Filtered'!A3 -> 2 | C9: ='GBG Filtered'!B3 -> Loss | D9: ='GBG Filtered'!C3 -> vs | E9: ='GBG Filtered'!D3 -> diogo10egas | F9: =IF('GBG Filtered'!E3 <> "", VLOOKUP(IFERROR(VLOOKUP('GBG Filtered'!E3, FormFixes, 2, false), 'GBG Filtered'!E3), PokemonIcons, 2, False), "") -> #REF! | G9: =IF('GBG Filtered'!F3 <> "", VLOOKUP(IFERROR(VLOOKUP('GBG Filtered'!F3, FormFixes, 2, false), 'GBG Filtered'!F3), PokemonIcons, 2, False), "") -> #REF! | H9: =IF('GBG Filtered'!G3 <> "", VLOOKUP(IFERROR(VLOOKUP('GBG Filtered'!G3, FormFixes, 2, false), 'GBG Filtered'!G3), PokemonIcons, 2, False), "") -> #REF! | I9: =IF('GBG Filtered'!H3 <> "", VLOOKUP(IFERROR(VLOOKUP('GBG Filtered'!H3, FormFixes, 2, false), 'GBG Filtered'!H3), PokemonIcons, 2, False), "") -> #REF! | J9: =IF('GBG Filtered'!I3 <> "", VLOOKUP(IFERROR(VLOOKUP('GBG Filtered'!I3, FormFixes, 2, false), 'GBG Filtered'!I3), PokemonIcons, 2, False), "") -> #REF! | K9: =IF('GBG Filtered'!J3 <> "", VLOOKUP(IFERROR(VLOOKUP('GBG Filtered'!J3, FormFixes, 2, false), 'GBG Filtered'!J3), PokemonIcons, 2, False), "") -> #REF! | O9: =IF('GBG Filtered'!N3 <> "", VLOOKUP(IFERROR(VLOOKUP('GBG Filtered'!N3, FormFixes, 2, false), 'GBG Filtered'!N3), PokemonIcons, 2, False), "") -> #REF! | P9: =IF('GBG Filtered'!O3 <> "", VLOOKUP(IFERROR(VLOOKUP('GBG Filtered'!O3, FormFixes, 2, false), 'GBG Filtered'!O3), PokemonIcons, 2, False), "") -> #REF! | Q9: =IF('GBG Filtered'!P3 <> "", VLOOKUP(IFERROR(VLOOKUP('GBG Filtered'!P3, FormFixes, 2, false), 'GBG Filtered'!P3), PokemonIcons, 2, False), "") -> #REF! | R9: =IF('GBG Filtered'!Q3 <> "", VLOOKUP(IFERROR(VLOOKUP('GBG Filtered'!Q3, FormFixes, 2, false), 'GBG Filtered'!Q3), PokemonIcons, 2, False), "") -> #REF! | T9: =IF('GBG Filtered'!S3 <> "", VLOOKUP(IFERROR(VLOOKUP('GBG Filtered'!S3, FormFixes, 2, false), 'GBG Filtered'!S3), PokemonIcons, 2, False), "") -> #REF! | U9: =IF('GBG Filtered'!T3 <> "", VLOOKUP(IFERROR(VLOOKUP('GBG Filtered'!T3, FormFixes, 2, false), 'GBG Filtered'!T3), PokemonIcons, 2, False), "") -> #REF! | V9: =IF('GBG Filtered'!U3 <> "", VLOOKUP(IFERROR(VLOOKUP('GBG Filtered'!U3, FormFixes, 2, false), 'GBG Filtered'!U3), PokemonIcons, 2, False), "") -> #REF! | W9: =IF('GBG Filtered'!V3 <> "", VLOOKUP(IFERROR(VLOOKUP('GBG Filtered'!V3, FormFixes, 2, false), 'GBG Filtered'!V3), PokemonIcons, 2, False), "") -> #REF! | Z9: =IF('GBG Filtered'!Y3 <> "", VLOOKUP(IFERROR(VLOOKUP('GBG Filtered'!Y3, FormFixes, 2, false), 'GBG Filtered'!Y3), PokemonIcons, 2, False), "") -> #REF! | AA9: =IF('GBG Filtered'!Z3 <> "", VLOOKUP('GBG Filtered'!Z3, TypeIcons, 2, False), "") -> #REF! | AB9: =IF('GBG Filtered'!AA3 <> "", VLOOKUP(IFERROR(VLOOKUP('GBG Filtered'!AA3, FormFixes, 2, false), 'GBG Filtered'!AA3), PokemonIcons, 2, False), "") -> #REF! | AC9: =IF('GBG Filtered'!AB3 <> "", VLOOKUP('GBG Filtered'!AB3, TypeIcons, 2, False), "") -> #REF! | AD9: ='GBG Filtered'!AC3 | AE9: ='GBG Filtered'!AD3 -> 1017 -> 1007 | AF9: ='GBG Filtered'!AE3 -> 1076
B10: ='GBG Filtered'!A4 -> 3 | C10: ='GBG Filtered'!B4 -> Loss | D10: ='GBG Filtered'!C4 -> vs | E10: ='GBG Filtered'!D4 -> Larateamo | F10: =IF('GBG Filtered'!E4 <> "", VLOOKUP(IFERROR(VLOOKUP('GBG Filtered'!E4, FormFixes, 2, false), 'GBG Filtered'!E4), PokemonIcons, 2, False), "") -> #REF! | G10: =IF('GBG Filtered'!F4 <> "", VLOOKUP(IFERROR(VLOOKUP('GBG Filtered'!F4, FormFixes, 2, false), 'GBG Filtered'!F4), PokemonIcons, 2, False), "") -> #REF! | H10: =IF('GBG Filtered'!G4 <> "", VLOOKUP(IFERROR(VLOOKUP('GBG Filtered'!G4, FormFixes, 2, false), 'GBG Filtered'!G4), PokemonIcons, 2, False), "") -> #REF! | I10: =IF('GBG Filtered'!H4 <> "", VLOOKUP(IFERROR(VLOOKUP('GBG Filtered'!H4, FormFixes, 2, false), 'GBG Filtered'!H4), PokemonIcons, 2, False), "") -> #REF! | J10: =IF('GBG Filtered'!I4 <> "", VLOOKUP(IFERROR(VLOOKUP('GBG Filtered'!I4, FormFixes, 2, false), 'GBG Filtered'!I4), PokemonIcons, 2, False), "") -> #REF! | K10: =IF('GBG Filtered'!J4 <> "", VLOOKUP(IFERROR(VLOOKUP('GBG Filtered'!J4, FormFixes, 2, false), 'GBG Filtered'!J4), PokemonIcons, 2, False), "") -> #REF! | O10: =IF('GBG Filtered'!N4 <> "", VLOOKUP(IFERROR(VLOOKUP('GBG Filtered'!N4, FormFixes, 2, false), 'GBG Filtered'!N4), PokemonIcons, 2, False), "") -> #REF! | P10: =IF('GBG Filtered'!O4 <> "", VLOOKUP(IFERROR(VLOOKUP('GBG Filtered'!O4, FormFixes, 2, false), 'GBG Filtered'!O4), PokemonIcons, 2, False), "") -> #REF! | Q10: =IF('GBG Filtered'!P4 <> "", VLOOKUP(IFERROR(VLOOKUP('GBG Filtered'!P4, FormFixes, 2, false), 'GBG Filtered'!P4), PokemonIcons, 2, False), "") -> #REF! | R10: =IF('GBG Filtered'!Q4 <> "", VLOOKUP(IFERROR(VLOOKUP('GBG Filtered'!Q4, FormFixes, 2, false), 'GBG Filtered'!Q4), PokemonIcons, 2, False), "") -> #REF! | T10: =IF('GBG Filtered'!S4 <> "", VLOOKUP(IFERROR(VLOOKUP('GBG Filtered'!S4, FormFixes, 2, false), 'GBG Filtered'!S4), PokemonIcons, 2, False), "") -> #REF! | U10: =IF('GBG Filtered'!T4 <> "", VLOOKUP(IFERROR(VLOOKUP('GBG Filtered'!T4, FormFixes, 2, false), 'GBG Filtered'!T4), PokemonIcons, 2, False), "") -> #REF! | V10: =IF('GBG Filtered'!U4 <> "", VLOOKUP(IFERROR(VLOOKUP('GBG Filtered'!U4, FormFixes, 2, false), 'GBG Filtered'!U4), PokemonIcons, 2, False), "") -> #REF! | W10: =IF('GBG Filtered'!V4 <> "", VLOOKUP(IFERROR(VLOOKUP('GBG Filtered'!V4, FormFixes, 2, false), 'GBG Filtered'!V4), PokemonIcons, 2, False), "") -> #REF! | Z10: =IF('GBG Filtered'!Y4 <> "", VLOOKUP(IFERROR(VLOOKUP('GBG Filtered'!Y4, FormFixes, 2, false), 'GBG Filtered'!Y4), PokemonIcons, 2, False), "") -> #REF! | AA10: =IF('GBG Filtered'!Z4 <> "", VLOOKUP('GBG Filtered'!Z4, TypeIcons, 2, False), "") -> #REF! | AB10: =IF('GBG Filtered'!AA4 <> "", VLOOKUP(IFERROR(VLOOKUP('GBG Filtered'!AA4, FormFixes, 2, false), 'GBG Filtered'!AA4), PokemonIcons, 2, False), "") -> #REF! | AC10: =IF('GBG Filtered'!AB4 <> "", VLOOKUP('GBG Filtered'!AB4, TypeIcons, 2, False), "") -> #REF! | AD10: ='GBG Filtered'!AC4 | AE10: ='GBG Filtered'!AD4 -> 1007 -> 1000 | AF10: ='GBG Filtered'!AE4 -> 1000
B11: ='GBG Filtered'!A5 -> 4 | C11: ='GBG Filtered'!B5 -> Loss | D11: ='GBG Filtered'!C5 -> vs | E11: ='GBG Filtered'!D5 -> thaoss | F11: =IF('GBG Filtered'!E5 <> "", VLOOKUP(IFERROR(VLOOKUP('GBG Filtered'!E5, FormFixes, 2, false), 'GBG Filtered'!E5), PokemonIcons, 2, False), "") -> #REF! | G11: =IF('GBG Filtered'!F5 <> "", VLOOKUP(IFERROR(VLOOKUP('GBG Filtered'!F5, FormFixes, 2, false), 'GBG Filtered'!F5), PokemonIcons, 2, False), "") -> #REF! | H11: =IF('GBG Filtered'!G5 <> "", VLOOKUP(IFERROR(VLOOKUP('GBG Filtered'!G5, FormFixes, 2, false), 'GBG Filtered'!G5), PokemonIcons, 2, False), "") -> #REF! | I11: =IF('GBG Filtered'!H5 <> "", VLOOKUP(IFERROR(VLOOKUP('GBG Filtered'!H5, FormFixes, 2, false), 'GBG Filtered'!H5), PokemonIcons, 2, False), "") -> #REF! | J11: =IF('GBG Filtered'!I5 <> "", VLOOKUP(IFERROR(VLOOKUP('GBG Filtered'!I5, FormFixes, 2, false), 'GBG Filtered'!I5), PokemonIcons, 2, False), "") -> #REF! | K11: =IF('GBG Filtered'!J5 <> "", VLOOKUP(IFERROR(VLOOKUP('GBG Filtered'!J5, FormFixes, 2, false), 'GBG Filtered'!J5), PokemonIcons, 2, False), "") -> #REF! | O11: =IF('GBG Filtered'!N5 <> "", VLOOKUP(IFERROR(VLOOKUP('GBG Filtered'!N5, FormFixes, 2, false), 'GBG Filtered'!N5), PokemonIcons, 2, False), "") -> #REF! | P11: =IF('GBG Filtered'!O5 <> "", VLOOKUP(IFERROR(VLOOKUP('GBG Filtered'!O5, FormFixes, 2, false), 'GBG Filtered'!O5), PokemonIcons, 2, False), "") -> #REF! | Q11: =IF('GBG Filtered'!P5 <> "", VLOOKUP(IFERROR(VLOOKUP('GBG Filtered'!P5, FormFixes, 2, false), 'GBG Filtered'!P5), PokemonIcons, 2, False), "") -> #REF! | R11: =IF('GBG Filtered'!Q5 <> "", VLOOKUP(IFERROR(VLOOKUP('GBG Filtered'!Q5, FormFixes, 2, false), 'GBG Filtered'!Q5), PokemonIcons, 2, False), "") -> #REF! | T11: =IF('GBG Filtered'!S5 <> "", VLOOKUP(IFERROR(VLOOKUP('GBG Filtered'!S5, FormFixes, 2, false), 'GBG Filtered'!S5), PokemonIcons, 2, False), "") -> #REF! | U11: =IF('GBG Filtered'!T5 <> "", VLOOKUP(IFERROR(VLOOKUP('GBG Filtered'!T5, FormFixes, 2, false), 'GBG Filtered'!T5), PokemonIcons, 2, False), "") -> #REF! | V11: =IF('GBG Filtered'!U5 <> "", VLOOKUP(IFERROR(VLOOKUP('GBG Filtered'!U5, FormFixes, 2, false), 'GBG Filtered'!U5), PokemonIcons, 2, False), "") -> #REF! | W11: =IF('GBG Filtered'!V5 <> "", VLOOKUP(IFERROR(VLOOKUP('GBG Filtered'!V5, FormFixes, 2, false), 'GBG Filtered'!V5), PokemonIcons, 2, False), "") -> #REF! | Z11: =IF('GBG Filtered'!Y5 <> "", VLOOKUP(IFERROR(VLOOKUP('GBG Filtered'!Y5, FormFixes, 2, false), 'GBG Filtered'!Y5), PokemonIcons, 2, False), "") -> #REF! | AA11: =IF('GBG Filtered'!Z5 <> "", VLOOKUP('GBG Filtered'!Z5, TypeIcons, 2, False), "") -> #REF! | AB11: =IF('GBG Filtered'!AA5 <> "", VLOOKUP(IFERROR(VLOOKUP('GBG Filtered'!AA5, FormFixes, 2, false), 'GBG Filtered'!AA5), PokemonIcons, 2, False), "") -> #REF! | AC11: =IF('GBG Filtered'!AB5 <> "", VLOOKUP('GBG Filtered'!AB5, TypeIcons, 2, False), "") -> #REF! | AD11: ='GBG Filtered'!AC5 | AE11: ='GBG Filtered'!AD5 -> 1000 -> 1000 | AF11: ='GBG Filtered'!AE5 -> 1000
B12: ='GBG Filtered'!A6 | C12: ='GBG Filtered'!B6 | D12: ='GBG Filtered'!C6 | E12: ='GBG Filtered'!D6 | F12: =IF('GBG Filtered'!E6 <> "", VLOOKUP(IFERROR(VLOOKUP('GBG Filtered'!E6, FormFixes, 2, false), 'GBG Filtered'!E6), PokemonIcons, 2, False), "") | G12: =IF('GBG Filtered'!F6 <> "", VLOOKUP(IFERROR(VLOOKUP('GBG Filtered'!F6, FormFixes, 2, false), 'GBG Filtered'!F6), PokemonIcons, 2, False), "") | H12: =IF('GBG Filtered'!G6 <> "", VLOOKUP(IFERROR(VLOOKUP('GBG Filtered'!G6, FormFixes, 2, false), 'GBG Filtered'!G6), PokemonIcons, 2, False), "") | I12: =IF('GBG Filtered'!H6 <> "", VLOOKUP(IFERROR(VLOOKUP('GBG Filtered'!H6, FormFixes, 2, false), 'GBG Filtered'!H6), PokemonIcons, 2, False), "") | J12: =IF('GBG Filtered'!I6 <> "", VLOOKUP(IFERROR(VLOOKUP('GBG Filtered'!I6, FormFixes, 2, false), 'GBG Filtered'!I6), PokemonIcons, 2, False), "") | K12: =IF('GBG Filtered'!J6 <> "", VLOOKUP(IFERROR(VLOOKUP('GBG Filtered'!J6, FormFixes, 2, false), 'GBG Filtered'!J6), PokemonIcons, 2, False), "") | O12: =IF('GBG Filtered'!N6 <> "", VLOOKUP(IFERROR(VLOOKUP('GBG Filtered'!N6, FormFixes, 2, false), 'GBG Filtered'!N6), PokemonIcons, 2, False), "") | P12: =IF('GBG Filtered'!O6 <> "", VLOOKUP(IFERROR(VLOOKUP('GBG Filtered'!O6, FormFixes, 2, false), 'GBG Filtered'!O6), PokemonIcons, 2, False), "") | Q12: =IF('GBG Filtered'!P6 <> "", VLOOKUP(IFERROR(VLOOKUP('GBG Filtered'!P6, FormFixes, 2, false), 'GBG Filtered'!P6), PokemonIcons, 2, False), "") | R12: =IF('GBG Filtered'!Q6 <> "", VLOOKUP(IFERROR(VLOOKUP('GBG Filtered'!Q6, FormFixes, 2, false), 'GBG Filtered'!Q6), PokemonIcons, 2, False), "") | T12: =IF('GBG Filtered'!S6 <> "", VLOOKUP(IFERROR(VLOOKUP('GBG Filtered'!S6, FormFixes, 2, false), 'GBG Filtered'!S6), PokemonIcons, 2, False), "") | U12: =IF('GBG Filtered'!T6 <> "", VLOOKUP(IFERROR(VLOOKUP('GBG Filtered'!T6, FormFixes, 2, false), 'GBG Filtered'!T6), PokemonIcons, 2, False), "") | V12: =IF('GBG Filtered'!U6 <> "", VLOOKUP(IFERROR(VLOOKUP('GBG Filtered'!U6, FormFixes, 2, false), 'GBG Filtered'!U6), PokemonIcons, 2, False), "") | W12: =IF('GBG Filtered'!V6 <> "", VLOOKUP(IFERROR(VLOOKUP('GBG Filtered'!V6, FormFixes, 2, false), 'GBG Filtered'!V6), PokemonIcons, 2, False), "") | Z12: =IF('GBG Filtered'!Y6 <> "", VLOOKUP(IFERROR(VLOOKUP('GBG Filtered'!Y6, FormFixes, 2, false), 'GBG Filtered'!Y6), PokemonIcons, 2, False), "") | AA12: =IF('GBG Filtered'!Z6 <> "", VLOOKUP('GBG Filtered'!Z6, TypeIcons, 2, False), "") | AB12: =IF('GBG Filtered'!AA6 <> "", VLOOKUP(IFERROR(VLOOKUP('GBG Filtered'!AA6, FormFixes, 2, false), 'GBG Filtered'!AA6), PokemonIcons, 2, False), "") | AC12: =IF('GBG Filtered'!AB6 <> "", VLOOKUP('GBG Filtered'!AB6, TypeIcons, 2, False), "") | AD12: ='GBG Filtered'!AC6 | AE12: ='GBG Filtered'!AD6 | AF12: ='GBG Filtered'!AE6
B13: ='GBG Filtered'!A7 | C13: ='GBG Filtered'!B7 | D13: ='GBG Filtered'!C7 | E13: ='GBG Filtered'!D7 | F13: =IF('GBG Filtered'!E7 <> "", VLOOKUP(IFERROR(VLOOKUP('GBG Filtered'!E7, FormFixes, 2, false), 'GBG Filtered'!E7), PokemonIcons, 2, False), "") | G13: =IF('GBG Filtered'!F7 <> "", VLOOKUP(IFERROR(VLOOKUP('GBG Filtered'!F7, FormFixes, 2, false), 'GBG Filtered'!F7), PokemonIcons, 2, False), "") | H13: =IF('GBG Filtered'!G7 <> "", VLOOKUP(IFERROR(VLOOKUP('GBG Filtered'!G7, FormFixes, 2, false), 'GBG Filtered'!G7), PokemonIcons, 2, False), "") | I13: =IF('GBG Filtered'!H7 <> "", VLOOKUP(IFERROR(VLOOKUP('GBG Filtered'!H7, FormFixes, 2, false), 'GBG Filtered'!H7), PokemonIcons, 2, False), "") | J13: =IF('GBG Filtered'!I7 <> "", VLOOKUP(IFERROR(VLOOKUP('GBG Filtered'!I7, FormFixes, 2, false), 'GBG Filtered'!I7), PokemonIcons, 2, False), "") | K13: =IF('GBG Filtered'!J7 <> "", VLOOKUP(IFERROR(VLOOKUP('GBG Filtered'!J7, FormFixes, 2, false), 'GBG Filtered'!J7), PokemonIcons, 2, False), "") | O13: =IF('GBG Filtered'!N7 <> "", VLOOKUP(IFERROR(VLOOKUP('GBG Filtered'!N7, FormFixes, 2, false), 'GBG Filtered'!N7), PokemonIcons, 2, False), "") | P13: =IF('GBG Filtered'!O7 <> "", VLOOKUP(IFERROR(VLOOKUP('GBG Filtered'!O7, FormFixes, 2, false), 'GBG Filtered'!O7), PokemonIcons, 2, False), "") | Q13: =IF('GBG Filtered'!P7 <> "", VLOOKUP(IFERROR(VLOOKUP('GBG Filtered'!P7, FormFixes, 2, false), 'GBG Filtered'!P7), PokemonIcons, 2, False), "") | R13: =IF('GBG Filtered'!Q7 <> "", VLOOKUP(IFERROR(VLOOKUP('GBG Filtered'!Q7, FormFixes, 2, false), 'GBG Filtered'!Q7), PokemonIcons, 2, False), "") | T13: =IF('GBG Filtered'!S7 <> "", VLOOKUP(IFERROR(VLOOKUP('GBG Filtered'!S7, FormFixes, 2, false), 'GBG Filtered'!S7), PokemonIcons, 2, False), "") | U13: =IF('GBG Filtered'!T7 <> "", VLOOKUP(IFERROR(VLOOKUP('GBG Filtered'!T7, FormFixes, 2, false), 'GBG Filtered'!T7), PokemonIcons, 2, False), "") | V13: =IF('GBG Filtered'!U7 <> "", VLOOKUP(IFERROR(VLOOKUP('GBG Filtered'!U7, FormFixes, 2, false), 'GBG Filtered'!U7), PokemonIcons, 2, False), "") | W13: =IF('GBG Filtered'!V7 <> "", VLOOKUP(IFERROR(VLOOKUP('GBG Filtered'!V7, FormFixes, 2, false), 'GBG Filtered'!V7), PokemonIcons, 2, False), "") | Z13: =IF('GBG Filtered'!Y7 <> "", VLOOKUP(IFERROR(VLOOKUP('GBG Filtered'!Y7, FormFixes, 2, false), 'GBG Filtered'!Y7), PokemonIcons, 2, False), "") | AA13: =IF('GBG Filtered'!Z7 <> "", VLOOKUP('GBG Filtered'!Z7, TypeIcons, 2, False), "") | AB13: =IF('GBG Filtered'!AA7 <> "", VLOOKUP(IFERROR(VLOOKUP('GBG Filtered'!AA7, FormFixes, 2, false), 'GBG Filtered'!AA7), PokemonIcons, 2, False), "") | AC13: =IF('GBG Filtered'!AB7 <> "", VLOOKUP('GBG Filtered'!AB7, TypeIcons, 2, False), "") | AD13: ='GBG Filtered'!AC7 | AE13: ='GBG Filtered'!AD7 | AF13: ='GBG Filtered'!AE7
B14: ='GBG Filtered'!A8 | C14: ='GBG Filtered'!B8 | D14: ='GBG Filtered'!C8 | E14: ='GBG Filtered'!D8 | F14: =IF('GBG Filtered'!E8 <> "", VLOOKUP(IFERROR(VLOOKUP('GBG Filtered'!E8, FormFixes, 2, false), 'GBG Filtered'!E8), PokemonIcons, 2, False), "") | G14: =IF('GBG Filtered'!F8 <> "", VLOOKUP(IFERROR(VLOOKUP('GBG Filtered'!F8, FormFixes, 2, false), 'GBG Filtered'!F8), PokemonIcons, 2, False), "") | H14: =IF('GBG Filtered'!G8 <> "", VLOOKUP(IFERROR(VLOOKUP('GBG Filtered'!G8, FormFixes, 2, false), 'GBG Filtered'!G8), PokemonIcons, 2, False), "") | I14: =IF('GBG Filtered'!H8 <> "", VLOOKUP(IFERROR(VLOOKUP('GBG Filtered'!H8, FormFixes, 2, false), 'GBG Filtered'!H8), PokemonIcons, 2, False), "") | J14: =IF('GBG Filtered'!I8 <> "", VLOOKUP(IFERROR(VLOOKUP('GBG Filtered'!I8, FormFixes, 2, false), 'GBG Filtered'!I8), PokemonIcons, 2, False), "") | K14: =IF('GBG Filtered'!J8 <> "", VLOOKUP(IFERROR(VLOOKUP('GBG Filtered'!J8, FormFixes, 2, false), 'GBG Filtered'!J8), PokemonIcons, 2, False), "") | O14: =IF('GBG Filtered'!N8 <> "", VLOOKUP(IFERROR(VLOOKUP('GBG Filtered'!N8, FormFixes, 2, false), 'GBG Filtered'!N8), PokemonIcons, 2, False), "") | P14: =IF('GBG Filtered'!O8 <> "", VLOOKUP(IFERROR(VLOOKUP('GBG Filtered'!O8, FormFixes, 2, false), 'GBG Filtered'!O8), PokemonIcons, 2, False), "") | Q14: =IF('GBG Filtered'!P8 <> "", VLOOKUP(IFERROR(VLOOKUP('GBG Filtered'!P8, FormFixes, 2, false), 'GBG Filtered'!P8), PokemonIcons, 2, False), "") | R14: =IF('GBG Filtered'!Q8 <> "", VLOOKUP(IFERROR(VLOOKUP('GBG Filtered'!Q8, FormFixes, 2, false), 'GBG Filtered'!Q8), PokemonIcons, 2, False), "") | T14: =IF('GBG Filtered'!S8 <> "", VLOOKUP(IFERROR(VLOOKUP('GBG Filtered'!S8, FormFixes, 2, false), 'GBG Filtered'!S8), PokemonIcons, 2, False), "") | U14: =IF('GBG Filtered'!T8 <> "", VLOOKUP(IFERROR(VLOOKUP('GBG Filtered'!T8, FormFixes, 2, false), 'GBG Filtered'!T8), PokemonIcons, 2, False), "") | V14: =IF('GBG Filtered'!U8 <> "", VLOOKUP(IFERROR(VLOOKUP('GBG Filtered'!U8, FormFixes, 2, false), 'GBG Filtered'!U8), PokemonIcons, 2, False), "") | W14: =IF('GBG Filtered'!V8 <> "", VLOOKUP(IFERROR(VLOOKUP('GBG Filtered'!V8, FormFixes, 2, false), 'GBG Filtered'!V8), PokemonIcons, 2, False), "") | Z14: =IF('GBG Filtered'!Y8 <> "", VLOOKUP(IFERROR(VLOOKUP('GBG Filtered'!Y8, FormFixes, 2, false), 'GBG Filtered'!Y8), PokemonIcons, 2, False), "") | AA14: =IF('GBG Filtered'!Z8 <> "", VLOOKUP('GBG Filtered'!Z8, TypeIcons, 2, False), "") | AB14: =IF('GBG Filtered'!AA8 <> "", VLOOKUP(IFERROR(VLOOKUP('GBG Filtered'!AA8, FormFixes, 2, false), 'GBG Filtered'!AA8), PokemonIcons, 2, False), "") | AC14: =IF('GBG Filtered'!AB8 <> "", VLOOKUP('GBG Filtered'!AB8, TypeIcons, 2, False), "") | AD14: ='GBG Filtered'!AC8 | AE14: ='GBG Filtered'!AD8 | AF14: ='GBG Filtered'!AE8
B15: ='GBG Filtered'!A9 | C15: ='GBG Filtered'!B9 | D15: ='GBG Filtered'!C9 | E15: ='GBG Filtered'!D9 | F15: =IF('GBG Filtered'!E9 <> "", VLOOKUP(IFERROR(VLOOKUP('GBG Filtered'!E9, FormFixes, 2, false), 'GBG Filtered'!E9), PokemonIcons, 2, False), "") | G15: =IF('GBG Filtered'!F9 <> "", VLOOKUP(IFERROR(VLOOKUP('GBG Filtered'!F9, FormFixes, 2, false), 'GBG Filtered'!F9), PokemonIcons, 2, False), "") | H15: =IF('GBG Filtered'!G9 <> "", VLOOKUP(IFERROR(VLOOKUP('GBG Filtered'!G9, FormFixes, 2, false), 'GBG Filtered'!G9), PokemonIcons, 2, False), "") | I15: =IF('GBG Filtered'!H9 <> "", VLOOKUP(IFERROR(VLOOKUP('GBG Filtered'!H9, FormFixes, 2, false), 'GBG Filtered'!H9), PokemonIcons, 2, False), "") | J15: =IF('GBG Filtered'!I9 <> "", VLOOKUP(IFERROR(VLOOKUP('GBG Filtered'!I9, FormFixes, 2, false), 'GBG Filtered'!I9), PokemonIcons, 2, False), "") | K15: =IF('GBG Filtered'!J9 <> "", VLOOKUP(IFERROR(VLOOKUP('GBG Filtered'!J9, FormFixes, 2, false), 'GBG Filtered'!J9), PokemonIcons, 2, False), "") | O15: =IF('GBG Filtered'!N9 <> "", VLOOKUP(IFERROR(VLOOKUP('GBG Filtered'!N9, FormFixes, 2, false), 'GBG Filtered'!N9), PokemonIcons, 2, False), "") | P15: =IF('GBG Filtered'!O9 <> "", VLOOKUP(IFERROR(VLOOKUP('GBG Filtered'!O9, FormFixes, 2, false), 'GBG Filtered'!O9), PokemonIcons, 2, False), "") | Q15: =IF('GBG Filtered'!P9 <> "", VLOOKUP(IFERROR(VLOOKUP('GBG Filtered'!P9, FormFixes, 2, false), 'GBG Filtered'!P9), PokemonIcons, 2, False), "") | R15: =IF('GBG Filtered'!Q9 <> "", VLOOKUP(IFERROR(VLOOKUP('GBG Filtered'!Q9, FormFixes, 2, false), 'GBG Filtered'!Q9), PokemonIcons, 2, False), "") | T15: =IF('GBG Filtered'!S9 <> "", VLOOKUP(IFERROR(VLOOKUP('GBG Filtered'!S9, FormFixes, 2, false), 'GBG Filtered'!S9), PokemonIcons, 2, False), "") | U15: =IF('GBG Filtered'!T9 <> "", VLOOKUP(IFERROR(VLOOKUP('GBG Filtered'!T9, FormFixes, 2, false), 'GBG Filtered'!T9), PokemonIcons, 2, False), "") | V15: =IF('GBG Filtered'!U9 <> "", VLOOKUP(IFERROR(VLOOKUP('GBG Filtered'!U9, FormFixes, 2, false), 'GBG Filtered'!U9), PokemonIcons, 2, False), "") | W15: =IF('GBG Filtered'!V9 <> "", VLOOKUP(IFERROR(VLOOKUP('GBG Filtered'!V9, FormFixes, 2, false), 'GBG Filtered'!V9), PokemonIcons, 2, False), "") | Z15: =IF('GBG Filtered'!Y9 <> "", VLOOKUP(IFERROR(VLOOKUP('GBG Filtered'!Y9, FormFixes, 2, false), 'GBG Filtered'!Y9), PokemonIcons, 2, False), "") | AA15: =IF('GBG Filtered'!Z9 <> "", VLOOKUP('GBG Filtered'!Z9, TypeIcons, 2, False), "") | AB15: =IF('GBG Filtered'!AA9 <> "", VLOOKUP(IFERROR(VLOOKUP('GBG Filtered'!AA9, FormFixes, 2, false), 'GBG Filtered'!AA9), PokemonIcons, 2, False), "") | AC15: =IF('GBG Filtered'!AB9 <> "", VLOOKUP('GBG Filtered'!AB9, TypeIcons, 2, False), "") | AD15: ='GBG Filtered'!AC9 | AE15: ='GBG Filtered'!AD9 | AF15: ='GBG Filtered'!AE9
B16: ='GBG Filtered'!A10 | C16: ='GBG Filtered'!B10 | D16: ='GBG Filtered'!C10 | E16: ='GBG Filtered'!D10 | F16: =IF('GBG Filtered'!E10 <> "", VLOOKUP(IFERROR(VLOOKUP('GBG Filtered'!E10, FormFixes, 2, false), 'GBG Filtered'!E10), PokemonIcons, 2, False), "") | G16: =IF('GBG Filtered'!F10 <> "", VLOOKUP(IFERROR(VLOOKUP('GBG Filtered'!F10, FormFixes, 2, false), 'GBG Filtered'!F10), PokemonIcons, 2, False), "") | H16: =IF('GBG Filtered'!G10 <> "", VLOOKUP(IFERROR(VLOOKUP('GBG Filtered'!G10, FormFixes, 2, false), 'GBG Filtered'!G10), PokemonIcons, 2, False), "") | I16: =IF('GBG Filtered'!H10 <> "", VLOOKUP(IFERROR(VLOOKUP('GBG Filtered'!H10, FormFixes, 2, false), 'GBG Filtered'!H10), PokemonIcons, 2, False), "") | J16: =IF('GBG Filtered'!I10 <> "", VLOOKUP(IFERROR(VLOOKUP('GBG Filtered'!I10, FormFixes, 2, false), 'GBG Filtered'!I10), PokemonIcons, 2, False), "") | K16: =IF('GBG Filtered'!J10 <> "", VLOOKUP(IFERROR(VLOOKUP('GBG Filtered'!J10, FormFixes, 2, false), 'GBG Filtered'!J10), PokemonIcons, 2, False), "") | O16: =IF('GBG Filtered'!N10 <> "", VLOOKUP(IFERROR(VLOOKUP('GBG Filtered'!N10, FormFixes, 2, false), 'GBG Filtered'!N10), PokemonIcons, 2, False), "") | P16: =IF('GBG Filtered'!O10 <> "", VLOOKUP(IFERROR(VLOOKUP('GBG Filtered'!O10, FormFixes, 2, false), 'GBG Filtered'!O10), PokemonIcons, 2, False), "") | Q16: =IF('GBG Filtered'!P10 <> "", VLOOKUP(IFERROR(VLOOKUP('GBG Filtered'!P10, FormFixes, 2, false), 'GBG Filtered'!P10), PokemonIcons, 2, False), "") | R16: =IF('GBG Filtered'!Q10 <> "", VLOOKUP(IFERROR(VLOOKUP('GBG Filtered'!Q10, FormFixes, 2, false), 'GBG Filtered'!Q10), PokemonIcons, 2, False), "") | T16: =IF('GBG Filtered'!S10 <> "", VLOOKUP(IFERROR(VLOOKUP('GBG Filtered'!S10, FormFixes, 2, false), 'GBG Filtered'!S10), PokemonIcons, 2, False), "") | U16: =IF('GBG Filtered'!T10 <> "", VLOOKUP(IFERROR(VLOOKUP('GBG Filtered'!T10, FormFixes, 2, false), 'GBG Filtered'!T10), PokemonIcons, 2, False), "") | V16: =IF('GBG Filtered'!U10 <> "", VLOOKUP(IFERROR(VLOOKUP('GBG Filtered'!U10, FormFixes, 2, false), 'GBG Filtered'!U10), PokemonIcons, 2, False), "") | W16: =IF('GBG Filtered'!V10 <> "", VLOOKUP(IFERROR(VLOOKUP('GBG Filtered'!V10, FormFixes, 2, false), 'GBG Filtered'!V10), PokemonIcons, 2, False), "") | Z16: =IF('GBG Filtered'!Y10 <> "", VLOOKUP(IFERROR(VLOOKUP('GBG Filtered'!Y10, FormFixes, 2, false), 'GBG Filtered'!Y10), PokemonIcons, 2, False), "") | AA16: =IF('GBG Filtered'!Z10 <> "", VLOOKUP('GBG Filtered'!Z10, TypeIcons, 2, False), "") | AB16: =IF('GBG Filtered'!AA10 <> "", VLOOKUP(IFERROR(VLOOKUP('GBG Filtered'!AA10, FormFixes, 2, false), 'GBG Filtered'!AA10), PokemonIcons, 2, False), "") | AC16: =IF('GBG Filtered'!AB10 <> "", VLOOKUP('GBG Filtered'!AB10, TypeIcons, 2, False), "") | AD16: ='GBG Filtered'!AC10 | AE16: ='GBG Filtered'!AD10 | AF16: ='GBG Filtered'!AE10
B17: ='GBG Filtered'!A11 | C17: ='GBG Filtered'!B11 | D17: ='GBG Filtered'!C11 | E17: ='GBG Filtered'!D11 | F17: =IF('GBG Filtered'!E11 <> "", VLOOKUP(IFERROR(VLOOKUP('GBG Filtered'!E11, FormFixes, 2, false), 'GBG Filtered'!E11), PokemonIcons, 2, False), "") | G17: =IF('GBG Filtered'!F11 <> "", VLOOKUP(IFERROR(VLOOKUP('GBG Filtered'!F11, FormFixes, 2, false), 'GBG Filtered'!F11), PokemonIcons, 2, False), "") | H17: =IF('GBG Filtered'!G11 <> "", VLOOKUP(IFERROR(VLOOKUP('GBG Filtered'!G11, FormFixes, 2, false), 'GBG Filtered'!G11), PokemonIcons, 2, False), "") | I17: =IF('GBG Filtered'!H11 <> "", VLOOKUP(IFERROR(VLOOKUP('GBG Filtered'!H11, FormFixes, 2, false), 'GBG Filtered'!H11), PokemonIcons, 2, False), "") | J17: =IF('GBG Filtered'!I11 <> "", VLOOKUP(IFERROR(VLOOKUP('GBG Filtered'!I11, FormFixes, 2, false), 'GBG Filtered'!I11), PokemonIcons, 2, False), "") | K17: =IF('GBG Filtered'!J11 <> "", VLOOKUP(IFERROR(VLOOKUP('GBG Filtered'!J11, FormFixes, 2, false), 'GBG Filtered'!J11), PokemonIcons, 2, False), "") | O17: =IF('GBG Filtered'!N11 <> "", VLOOKUP(IFERROR(VLOOKUP('GBG Filtered'!N11, FormFixes, 2, false), 'GBG Filtered'!N11), PokemonIcons, 2, False), "") | P17: =IF('GBG Filtered'!O11 <> "", VLOOKUP(IFERROR(VLOOKUP('GBG Filtered'!O11, FormFixes, 2, false), 'GBG Filtered'!O11), PokemonIcons, 2, False), "") | Q17: =IF('GBG Filtered'!P11 <> "", VLOOKUP(IFERROR(VLOOKUP('GBG Filtered'!P11, FormFixes, 2, false), 'GBG Filtered'!P11), PokemonIcons, 2, False), "") | R17: =IF('GBG Filtered'!Q11 <> "", VLOOKUP(IFERROR(VLOOKUP('GBG Filtered'!Q11, FormFixes, 2, false), 'GBG Filtered'!Q11), PokemonIcons, 2, False), "") | T17: =IF('GBG Filtered'!S11 <> "", VLOOKUP(IFERROR(VLOOKUP('GBG Filtered'!S11, FormFixes, 2, false), 'GBG Filtered'!S11), PokemonIcons, 2, False), "") | U17: =IF('GBG Filtered'!T11 <> "", VLOOKUP(IFERROR(VLOOKUP('GBG Filtered'!T11, FormFixes, 2, false), 'GBG Filtered'!T11), PokemonIcons, 2, False), "") | V17: =IF('GBG Filtered'!U11 <> "", VLOOKUP(IFERROR(VLOOKUP('GBG Filtered'!U11, FormFixes, 2, false), 'GBG Filtered'!U11), PokemonIcons, 2, False), "") | W17: =IF('GBG Filtered'!V11 <> "", VLOOKUP(IFERROR(VLOOKUP('GBG Filtered'!V11, FormFixes, 2, false), 'GBG Filtered'!V11), PokemonIcons, 2, False), "") | Z17: =IF('GBG Filtered'!Y11 <> "", VLOOKUP(IFERROR(VLOOKUP('GBG Filtered'!Y11, FormFixes, 2, false), 'GBG Filtered'!Y11), PokemonIcons, 2, False), "") | AA17: =IF('GBG Filtered'!Z11 <> "", VLOOKUP('GBG Filtered'!Z11, TypeIcons, 2, False), "") | AB17: =IF('GBG Filtered'!AA11 <> "", VLOOKUP(IFERROR(VLOOKUP('GBG Filtered'!AA11, FormFixes, 2, false), 'GBG Filtered'!AA11), PokemonIcons, 2, False), "") | AC17: =IF('GBG Filtered'!AB11 <> "", VLOOKUP('GBG Filtered'!AB11, TypeIcons, 2, False), "") | AD17: ='GBG Filtered'!AC11 | AE17: ='GBG Filtered'!AD11 | AF17: ='GBG Filtered'!AE11
B18: ='GBG Filtered'!A12 | C18: ='GBG Filtered'!B12 | D18: ='GBG Filtered'!C12 | E18: ='GBG Filtered'!D12 | F18: =IF('GBG Filtered'!E12 <> "", VLOOKUP(IFERROR(VLOOKUP('GBG Filtered'!E12, FormFixes, 2, false), 'GBG Filtered'!E12), PokemonIcons, 2, False), "") | G18: =IF('GBG Filtered'!F12 <> "", VLOOKUP(IFERROR(VLOOKUP('GBG Filtered'!F12, FormFixes, 2, false), 'GBG Filtered'!F12), PokemonIcons, 2, False), "") | H18: =IF('GBG Filtered'!G12 <> "", VLOOKUP(IFERROR(VLOOKUP('GBG Filtered'!G12, FormFixes, 2, false), 'GBG Filtered'!G12), PokemonIcons, 2, False), "") | I18: =IF('GBG Filtered'!H12 <> "", VLOOKUP(IFERROR(VLOOKUP('GBG Filtered'!H12, FormFixes, 2, false), 'GBG Filtered'!H12), PokemonIcons, 2, False), "") | J18: =IF('GBG Filtered'!I12 <> "", VLOOKUP(IFERROR(VLOOKUP('GBG Filtered'!I12, FormFixes, 2, false), 'GBG Filtered'!I12), PokemonIcons, 2, False), "") | K18: =IF('GBG Filtered'!J12 <> "", VLOOKUP(IFERROR(VLOOKUP('GBG Filtered'!J12, FormFixes, 2, false), 'GBG Filtered'!J12), PokemonIcons, 2, False), "") | O18: =IF('GBG Filtered'!N12 <> "", VLOOKUP(IFERROR(VLOOKUP('GBG Filtered'!N12, FormFixes, 2, false), 'GBG Filtered'!N12), PokemonIcons, 2, False), "") | P18: =IF('GBG Filtered'!O12 <> "", VLOOKUP(IFERROR(VLOOKUP('GBG Filtered'!O12, FormFixes, 2, false), 'GBG Filtered'!O12), PokemonIcons, 2, False), "") | Q18: =IF('GBG Filtered'!P12 <> "", VLOOKUP(IFERROR(VLOOKUP('GBG Filtered'!P12, FormFixes, 2, false), 'GBG Filtered'!P12), PokemonIcons, 2, False), "") | R18: =IF('GBG Filtered'!Q12 <> "", VLOOKUP(IFERROR(VLOOKUP('GBG Filtered'!Q12, FormFixes, 2, false), 'GBG Filtered'!Q12), PokemonIcons, 2, False), "") | T18: =IF('GBG Filtered'!S12 <> "", VLOOKUP(IFERROR(VLOOKUP('GBG Filtered'!S12, FormFixes, 2, false), 'GBG Filtered'!S12), PokemonIcons, 2, False), "") | U18: =IF('GBG Filtered'!T12 <> "", VLOOKUP(IFERROR(VLOOKUP('GBG Filtered'!T12, FormFixes, 2, false), 'GBG Filtered'!T12), PokemonIcons, 2, False), "") | V18: =IF('GBG Filtered'!U12 <> "", VLOOKUP(IFERROR(VLOOKUP('GBG Filtered'!U12, FormFixes, 2, false), 'GBG Filtered'!U12), PokemonIcons, 2, False), "") | W18: =IF('GBG Filtered'!V12 <> "", VLOOKUP(IFERROR(VLOOKUP('GBG Filtered'!V12, FormFixes, 2, false), 'GBG Filtered'!V12), PokemonIcons, 2, False), "") | Z18: =IF('GBG Filtered'!Y12 <> "", VLOOKUP(IFERROR(VLOOKUP('GBG Filtered'!Y12, FormFixes, 2, false), 'GBG Filtered'!Y12), PokemonIcons, 2, False), "") | AA18: =IF('GBG Filtered'!Z12 <> "", VLOOKUP('GBG Filtered'!Z12, TypeIcons, 2, False), "") | AB18: =IF('GBG Filtered'!AA12 <> "", VLOOKUP(IFERROR(VLOOKUP('GBG Filtered'!AA12, FormFixes, 2, false), 'GBG Filtered'!AA12), PokemonIcons, 2, False), "") | AC18: =IF('GBG Filtered'!AB12 <> "", VLOOKUP('GBG Filtered'!AB12, TypeIcons, 2, False), "") | AD18: ='GBG Filtered'!AC12 | AE18: ='GBG Filtered'!AD12 | AF18: ='GBG Filtered'!AE12
B19: ='GBG Filtered'!A13 | C19: ='GBG Filtered'!B13 | D19: ='GBG Filtered'!C13 | E19: ='GBG Filtered'!D13 | F19: =IF('GBG Filtered'!E13 <> "", VLOOKUP(IFERROR(VLOOKUP('GBG Filtered'!E13, FormFixes, 2, false), 'GBG Filtered'!E13), PokemonIcons, 2, False), "") | G19: =IF('GBG Filtered'!F13 <> "", VLOOKUP(IFERROR(VLOOKUP('GBG Filtered'!F13, FormFixes, 2, false), 'GBG Filtered'!F13), PokemonIcons, 2, False), "") | H19: =IF('GBG Filtered'!G13 <> "", VLOOKUP(IFERROR(VLOOKUP('GBG Filtered'!G13, FormFixes, 2, false), 'GBG Filtered'!G13), PokemonIcons, 2, False), "") | I19: =IF('GBG Filtered'!H13 <> "", VLOOKUP(IFERROR(VLOOKUP('GBG Filtered'!H13, FormFixes, 2, false), 'GBG Filtered'!H13), PokemonIcons, 2, False), "") | J19: =IF('GBG Filtered'!I13 <> "", VLOOKUP(IFERROR(VLOOKUP('GBG Filtered'!I13, FormFixes, 2, false), 'GBG Filtered'!I13), PokemonIcons, 2, False), "") | K19: =IF('GBG Filtered'!J13 <> "", VLOOKUP(IFERROR(VLOOKUP('GBG Filtered'!J13, FormFixes, 2, false), 'GBG Filtered'!J13), PokemonIcons, 2, False), "") | O19: =IF('GBG Filtered'!N13 <> "", VLOOKUP(IFERROR(VLOOKUP('GBG Filtered'!N13, FormFixes, 2, false), 'GBG Filtered'!N13), PokemonIcons, 2, False), "") | P19: =IF('GBG Filtered'!O13 <> "", VLOOKUP(IFERROR(VLOOKUP('GBG Filtered'!O13, FormFixes, 2, false), 'GBG Filtered'!O13), PokemonIcons, 2, False), "") | Q19: =IF('GBG Filtered'!P13 <> "", VLOOKUP(IFERROR(VLOOKUP('GBG Filtered'!P13, FormFixes, 2, false), 'GBG Filtered'!P13), PokemonIcons, 2, False), "") | R19: =IF('GBG Filtered'!Q13 <> "", VLOOKUP(IFERROR(VLOOKUP('GBG Filtered'!Q13, FormFixes, 2, false), 'GBG Filtered'!Q13), PokemonIcons, 2, False), "") | T19: =IF('GBG Filtered'!S13 <> "", VLOOKUP(IFERROR(VLOOKUP('GBG Filtered'!S13, FormFixes, 2, false), 'GBG Filtered'!S13), PokemonIcons, 2, False), "") | U19: =IF('GBG Filtered'!T13 <> "", VLOOKUP(IFERROR(VLOOKUP('GBG Filtered'!T13, FormFixes, 2, false), 'GBG Filtered'!T13), PokemonIcons, 2, False), "") | V19: =IF('GBG Filtered'!U13 <> "", VLOOKUP(IFERROR(VLOOKUP('GBG Filtered'!U13, FormFixes, 2, false), 'GBG Filtered'!U13), PokemonIcons, 2, False), "") | W19: =IF('GBG Filtered'!V13 <> "", VLOOKUP(IFERROR(VLOOKUP('GBG Filtered'!V13, FormFixes, 2, false), 'GBG Filtered'!V13), PokemonIcons, 2, False), "") | Z19: =IF('GBG Filtered'!Y13 <> "", VLOOKUP(IFERROR(VLOOKUP('GBG Filtered'!Y13, FormFixes, 2, false), 'GBG Filtered'!Y13), PokemonIcons, 2, False), "") | AA19: =IF('GBG Filtered'!Z13 <> "", VLOOKUP('GBG Filtered'!Z13, TypeIcons, 2, False), "") | AB19: =IF('GBG Filtered'!AA13 <> "", VLOOKUP(IFERROR(VLOOKUP('GBG Filtered'!AA13, FormFixes, 2, false), 'GBG Filtered'!AA13), PokemonIcons, 2, False), "") | AC19: =IF('GBG Filtered'!AB13 <> "", VLOOKUP('GBG Filtered'!AB13, TypeIcons, 2, False), "") | AD19: ='GBG Filtered'!AC13 | AE19: ='GBG Filtered'!AD13 | AF19: ='GBG Filtered'!AE13
... B107: ='GBG Filtered'!A101 | C107: ='GBG Filtered'!B101 | D107: ='GBG Filtered'!C101 | E107: ='GBG Filtered'!D101 | F107: =IF('GBG Filtered'!E101 <> "", VLOOKUP(IFERROR(VLOOKUP('GBG Filtered'!E101, FormFixes, 2, false), 'GBG Filtered'!E101), PokemonIcons, 2, False), "") | G107: =IF('GBG Filtered'!F101 <> "", VLOOKUP(IFERROR(VLOOKUP('GBG Filtered'!F101, FormFixes, 2, false), 'GBG Filtered'!F101), PokemonIcons, 2, False), "") | H107: =IF('GBG Filtered'!G101 <> "", VLOOKUP(IFERROR(VLOOKUP('GBG Filtered'!G101, FormFixes, 2, false), 'GBG Filtered'!G101), PokemonIcons, 2, False), "") | I107: =IF('GBG Filtered'!H101 <> "", VLOOKUP(IFERROR(VLOOKUP('GBG Filtered'!H101, FormFixes, 2, false), 'GBG Filtered'!H101), PokemonIcons, 2, False), "") | J107: =IF('GBG Filtered'!I101 <> "", VLOOKUP(IFERROR(VLOOKUP('GBG Filtered'!I101, FormFixes, 2, false), 'GBG Filtered'!I101), PokemonIcons, 2, False), "") | K107: =IF('GBG Filtered'!J101 <> "", VLOOKUP(IFERROR(VLOOKUP('GBG Filtered'!J101, FormFixes, 2, false), 'GBG Filtered'!J101), PokemonIcons, 2, False), "") | O107: =IF('GBG Filtered'!N101 <> "", VLOOKUP(IFERROR(VLOOKUP('GBG Filtered'!N101, FormFixes, 2, false), 'GBG Filtered'!N101), PokemonIcons, 2, False), "") | P107: =IF('GBG Filtered'!O101 <> "", VLOOKUP(IFERROR(VLOOKUP('GBG Filtered'!O101, FormFixes, 2, false), 'GBG Filtered'!O101), PokemonIcons, 2, False), "") | Q107: =IF('GBG Filtered'!P101 <> "", VLOOKUP(IFERROR(VLOOKUP('GBG Filtered'!P101, FormFixes, 2, false), 'GBG Filtered'!P101), PokemonIcons, 2, False), "") | R107: =IF('GBG Filtered'!Q101 <> "", VLOOKUP(IFERROR(VLOOKUP('GBG Filtered'!Q101, FormFixes, 2, false), 'GBG Filtered'!Q101), PokemonIcons, 2, False), "") | T107: =IF('GBG Filtered'!S101 <> "", VLOOKUP(IFERROR(VLOOKUP('GBG Filtered'!S101, FormFixes, 2, false), 'GBG Filtered'!S101), PokemonIcons, 2, False), "") | U107: =IF('GBG Filtered'!T101 <> "", VLOOKUP(IFERROR(VLOOKUP('GBG Filtered'!T101, FormFixes, 2, false), 'GBG Filtered'!T101), PokemonIcons, 2, False), "") | V107: =IF('GBG Filtered'!U101 <> "", VLOOKUP(IFERROR(VLOOKUP('GBG Filtered'!U101, FormFixes, 2, false), 'GBG Filtered'!U101), PokemonIcons, 2, False), "") | W107: =IF('GBG Filtered'!V101 <> "", VLOOKUP(IFERROR(VLOOKUP('GBG Filtered'!V101, FormFixes, 2, false), 'GBG Filtered'!V101), PokemonIcons, 2, False), "") | Z107: =IF('GBG Filtered'!Y101 <> "", VLOOKUP(IFERROR(VLOOKUP('GBG Filtered'!Y101, FormFixes, 2, false), 'GBG Filtered'!Y101), PokemonIcons, 2, False), "") | AA107: =IF('GBG Filtered'!Z101 <> "", VLOOKUP('GBG Filtered'!Z101, TypeIcons, 2, False), "") | AB107: =IF('GBG Filtered'!AA101 <> "", VLOOKUP(IFERROR(VLOOKUP('GBG Filtered'!AA101, FormFixes, 2, false), 'GBG Filtered'!AA101), PokemonIcons, 2, False), "") | AC107: =IF('GBG Filtered'!AB101 <> "", VLOOKUP('GBG Filtered'!AB101, TypeIcons, 2, False), "") | AD107: ='GBG Filtered'!AC101 | AE107: ='GBG Filtered'!AD101 | AF107: ='GBG Filtered'!AE101

Sheet GBG DASHBOARD
A1: Desired Result | B1: ='Game By Game'!E4 -> -any- | D1: Col2 | E1: =IF(B1<>"-any-", "AND Col2 = '"&B1&"'", "")
A2: Desired Opponent Mon on Team | B2: ='Game By Game'!I4 -> -any- | D2: Col5 thru Col10 | E2: =IF(B2 <> "-any-", " AND (Col5 = '"&B2&"' OR Col6 = '"&B2&"' OR Col7 = '"&B2&"' OR Col8 = '"&B2&"' OR Col9 = '"&B2&"' OR Col10 = '"&B2&"')", "")
A3: Desired Opponent Lead | B3: ='Game By Game'!U3 -> -any- | D3: Col19 and Col20 | E3: =IF(B3 <> "-any-", " AND (Col19 = '"&B3&"' OR Col20 = '"&B3&"')", "")
A4: Desired Opponent Back | B4: ='Game By Game'!U4 -> -any- | D4: Col21 and Col22 | E4: =IF(B4 <> "-any-", " AND (Col21 = '"&B4&"' OR Col22 = '"&B4&"')", "")
A5: Desired Player Use | D5: Col14 thru Col17 | E5: =IF(B5<>"", " AND (Col14 = '"&B5&"' OR Col15 = '"&B5&"' OR Col16 = '"&B5&"' OR Col17 = '"&B5&"')", "")
A6: Desired Player Lead | B6: ='Game By Game'!P3 -> -any- | D6: Col14 and Col15 | E6: =IF(B6 <> "-any-", " AND (Col14 = '"&B6&"' OR Col15 = '"&B6&"')", "")
A7: Desired Player Back | B7: ='Game By Game'!P4 -> -any- | D7: Col16 and Col17 | E7: =IF(B7 <> "-any-", " AND (Col16 = '"&B7&"' OR Col17 = '"&B7&"')", "")
A8: Desired Player Tera | B8: ='Game By Game'!Z4 -> -any- | D8: Col25 | E8: =IF(B8<>"-any-", " AND Col25 = '"&B8&"'", "")
A9: Desired OTS | B9: ='Game By Game'!AD4 -> -any- | D9: Col29 | E9: =IF(B10<>"-any-", " AND Col29 = '"&B10&"'", "")
A10: Desired OTS clean | B10: =IF(B9 = "OTS", "YES", IF(B9 = "CTS", "", "-any-")) -> -any-
A11: -any-
A12: Win
A13: Loss
A15: -any-
A16: OTS
A17: CTS

Sheet GBG Data
B1: Game Num | C1: Result | D1: VS | E1: Opp Name | F1: OppMon1 | G1: OppMon2 | H1: OppMon3 | I1: OppMon4 | J1: OppMon5 | K1: OppMon6 | O1: PlayerLead1 | P1: PlayerLead2 | Q1: PlayerBack1 | R1: PlayerBack2 | T1: OppLead1 | U1: OppLead2 | V1: OppBack1 | W1: OppBack2 | Z1: PlayerTeraMon | AA1: PlayerTeraType | AB1: OppTeraMon | AC1: OppTeraType | AD1: OTS | AE1: ELO | AF1: Opp ELO
B2: =IF(HomePage!C14 <> "", HomePage!B14, "") -> 1 | C2: ='Base Data'!DW3 -> Loss | D2: =IF(HomePage!C14 <> "", "vs", "") -> vs | E2: ='Base Data'!DP3 -> DoByG | F2: ='Base Data'!DQ3 -> Clefable | G2: ='Base Data'!DR3 -> Exeggutor | H2: ='Base Data'!DS3 -> Snorlax | I2: ='Base Data'!DT3 -> Dragonite | J2: ='Base Data'!DU3 -> Gyarados | K2: ='Base Data'!DV3 -> Hitmonlee | O2: ='Base Data'!CX3 -> Alcremie-Matcha-Cream | P2: ='Base Data'!CY3 -> Skeledirge | Q2: ='Base Data'!CV3 -> Salamence | R2: ='Base Data'!CW3 -> Weavile | T2: ='Base Data'!CZ3 -> Hitmonlee | U2: ='Base Data'!DA3 -> Gyarados | V2: ='Base Data'!DB3 -> Clefable | W2: ='Base Data'!DC3 -> Dragonite | Z2: ='Base Data'!DE3 -> Skeledirge | AA2: ='Base Data'!DF3 -> Grass | AB2: ='Base Data'!DG3 -> Gyarados | AC2: ='Base Data'!DH3 -> Flying | AD2: =IF('Base Data'!Y3 = "ots", "YES", "") | AE2: =SWITCH('Base Data'!EE3, "? -> ?", "pending", "--- -> ---", "unranked", " -> ", "", 'Base Data'!EE3) -> 1032 -> 1017 | AF2: =IF(AND('Base Data'!EF3 <> "",'Base Data'!EF3 <> "?",'Base Data'!EF3 <> "---"), 'Base Data'!EF3, "") -> 1037
B3: =IF(HomePage!C15 <> "", HomePage!B15, "") -> 2 | C3: ='Base Data'!DW4 -> Loss | D3: =IF(HomePage!C15 <> "", "vs", "") -> vs | E3: ='Base Data'!DP4 -> diogo10egas | F3: ='Base Data'!DQ4 -> Annihilape | G3: ='Base Data'!DR4 -> Maushold | H3: ='Base Data'!DS4 -> Pelipper | I3: ='Base Data'!DT4 -> Archaludon | J3: ='Base Data'!DU4 -> Ogerpon-Wellspring | K3: ='Base Data'!DV4 -> Umbreon | O3: ='Base Data'!CX4 -> Alcremie-Matcha-Cream | P3: ='Base Data'!CY4 -> Salamence | Q3: ='Base Data'!CV4 -> Gholdengo | R3: ='Base Data'!CW4 -> Weavile | T3: ='Base Data'!CZ4 -> Annihilape | U3: ='Base Data'!DA4 -> Umbreon | V3: ='Base Data'!DB4 -> Archaludon | W3: ='Base Data'!DC4 -> Ogerpon-Wellspring | Z3: ='Base Data'!DE4 -> Gholdengo | AA3: ='Base Data'!DF4 -> Steel | AB3: ='Base Data'!DG4 -> Umbreon | AC3: ='Base Data'!DH4 -> Fairy | AD3: =IF('Base Data'!Y4 = "ots", "YES", "") | AE3: =SWITCH('Base Data'!EE4, "? -> ?", "pending", "--- -> ---", "unranked", " -> ", "", 'Base Data'!EE4) -> 1017 -> 1007 | AF3: =IF(AND('Base Data'!EF4 <> "",'Base Data'!EF4 <> "?",'Base Data'!EF4 <> "---"), 'Base Data'!EF4, "") -> 1076
B4: =IF(HomePage!C16 <> "", HomePage!B16, "") -> 3 | C4: ='Base Data'!DW5 -> Loss | D4: =IF(HomePage!C16 <> "", "vs", "") -> vs | E4: ='Base Data'!DP5 -> Larateamo | F4: ='Base Data'!DQ5 -> Chien-Pao | G4: ='Base Data'!DR5 -> Urshifu-* | H4: ='Base Data'!DS5 -> Raging Bolt | I4: ='Base Data'!DT5 -> Incineroar | J4: ='Base Data'!DU5 -> Amoonguss | K4: ='Base Data'!DV5 -> Gholdengo | O4: ='Base Data'!CX5 -> Alcremie-Matcha-Cream | P4: ='Base Data'!CY5 -> Skeledirge | Q4: ='Base Data'!CV5 -> Exeggutor-Alola | R4: ='Base Data'!CW5 -> Weavile | T4: ='Base Data'!CZ5 -> Raging Bolt | U4: ='Base Data'!DA5 -> Urshifu-Rapid-Strike | V4: ='Base Data'!DB5 -> Incineroar | W4: ='Base Data'!DC5 -> Amoonguss | Z4: ='Base Data'!DE5 -> Skeledirge | AA4: ='Base Data'!DF5 -> Grass | AB4: ='Base Data'!DG5 -> Amoonguss | AC4: ='Base Data'!DH5 -> Water | AD4: =IF('Base Data'!Y5 = "ots", "YES", "") | AE4: =SWITCH('Base Data'!EE5, "? -> ?", "pending", "--- -> ---", "unranked", " -> ", "", 'Base Data'!EE5) -> 1007 -> 1000 | AF4: =IF(AND('Base Data'!EF5 <> "",'Base Data'!EF5 <> "?",'Base Data'!EF5 <> "---"), 'Base Data'!EF5, "") -> 1000
B5: =IF(HomePage!C17 <> "", HomePage!B17, "") -> 4 | C5: ='Base Data'!DW6 -> Loss | D5: =IF(HomePage!C17 <> "", "vs", "") -> vs | E5: ='Base Data'!DP6 -> thaoss | F5: ='Base Data'!DQ6 -> Incineroar | G5: ='Base Data'!DR6 -> Rillaboom | H5: ='Base Data'!DS6 -> Ursaluna-Bloodmoon | I5: ='Base Data'!DT6 -> Farigiraf | J5: ='Base Data'!DU6 -> Raging Bolt | K5: ='Base Data'!DV6 -> Urshifu-* | O5: ='Base Data'!CX6 -> Salamence | P5: ='Base Data'!CY6 -> Alcremie-Matcha-Cream | Q5: ='Base Data'!CV6 -> Weavile | R5: ='Base Data'!CW6 -> Skeledirge | T5: ='Base Data'!CZ6 -> Urshifu-Rapid-Strike | U5: ='Base Data'!DA6 -> Farigiraf | V5: ='Base Data'!DB6 -> Ursaluna-Bloodmoon | W5: ='Base Data'!DC6 -> Incineroar | Z5: ='Base Data'!DE6 -> Salamence | AA5: ='Base Data'!DF6 -> Flying | AB5: ='Base Data'!DG6 -> Ursaluna-Bloodmoon | AC5: ='Base Data'!DH6 -> Normal | AD5: =IF('Base Data'!Y6 = "ots", "YES", "") | AE5: =SWITCH('Base Data'!EE6, "? -> ?", "pending", "--- -> ---", "unranked", " -> ", "", 'Base Data'!EE6) -> 1000 -> 1000 | AF5: =IF(AND('Base Data'!EF6 <> "",'Base Data'!EF6 <> "?",'Base Data'!EF6 <> "---"), 'Base Data'!EF6, "") -> 1000
B6: =IF(HomePage!C18 <> "", HomePage!B18, "") | C6: ='Base Data'!DW7 | D6: =IF(HomePage!C18 <> "", "vs", "") | E6: ='Base Data'!DP7 | F6: ='Base Data'!DQ7 | G6: ='Base Data'!DR7 | H6: ='Base Data'!DS7 | I6: ='Base Data'!DT7 | J6: ='Base Data'!DU7 | K6: ='Base Data'!DV7 | O6: ='Base Data'!CX7 | P6: ='Base Data'!CY7 | Q6: ='Base Data'!CV7 | R6: ='Base Data'!CW7 | T6: ='Base Data'!CZ7 | U6: ='Base Data'!DA7 | V6: ='Base Data'!DB7 | W6: ='Base Data'!DC7 | Z6: ='Base Data'!DE7 | AA6: ='Base Data'!DF7 | AB6: ='Base Data'!DG7 | AC6: ='Base Data'!DH7 | AD6: =IF('Base Data'!Y7 = "ots", "YES", "") | AE6: =SWITCH('Base Data'!EE7, "? -> ?", "pending", "--- -> ---", "unranked", " -> ", "", 'Base Data'!EE7) | AF6: =IF(AND('Base Data'!EF7 <> "",'Base Data'!EF7 <> "?",'Base Data'!EF7 <> "---"), 'Base Data'!EF7, "")
B7: =IF(HomePage!C19 <> "", HomePage!B19, "") | C7: ='Base Data'!DW8 | D7: =IF(HomePage!C19 <> "", "vs", "") | E7: ='Base Data'!DP8 | F7: ='Base Data'!DQ8 | G7: ='Base Data'!DR8 | H7: ='Base Data'!DS8 | I7: ='Base Data'!DT8 | J7: ='Base Data'!DU8 | K7: ='Base Data'!DV8 | O7: ='Base Data'!CX8 | P7: ='Base Data'!CY8 | Q7: ='Base Data'!CV8 | R7: ='Base Data'!CW8 | T7: ='Base Data'!CZ8 | U7: ='Base Data'!DA8 | V7: ='Base Data'!DB8 | W7: ='Base Data'!DC8 | Z7: ='Base Data'!DE8 | AA7: ='Base Data'!DF8 | AB7: ='Base Data'!DG8 | AC7: ='Base Data'!DH8 | AD7: =IF('Base Data'!Y8 = "ots", "YES", "") | AE7: =SWITCH('Base Data'!EE8, "? -> ?", "pending", "--- -> ---", "unranked", " -> ", "", 'Base Data'!EE8) | AF7: =IF(AND('Base Data'!EF8 <> "",'Base Data'!EF8 <> "?",'Base Data'!EF8 <> "---"), 'Base Data'!EF8, "")
B8: =IF(HomePage!C20 <> "", HomePage!B20, "") | C8: ='Base Data'!DW9 | D8: =IF(HomePage!C20 <> "", "vs", "") | E8: ='Base Data'!DP9 | F8: ='Base Data'!DQ9 | G8: ='Base Data'!DR9 | H8: ='Base Data'!DS9 | I8: ='Base Data'!DT9 | J8: ='Base Data'!DU9 | K8: ='Base Data'!DV9 | O8: ='Base Data'!CX9 | P8: ='Base Data'!CY9 | Q8: ='Base Data'!CV9 | R8: ='Base Data'!CW9 | T8: ='Base Data'!CZ9 | U8: ='Base Data'!DA9 | V8: ='Base Data'!DB9 | W8: ='Base Data'!DC9 | Z8: ='Base Data'!DE9 | AA8: ='Base Data'!DF9 | AB8: ='Base Data'!DG9 | AC8: ='Base Data'!DH9 | AD8: =IF('Base Data'!Y9 = "ots", "YES", "") | AE8: =SWITCH('Base Data'!EE9, "? -> ?", "pending", "--- -> ---", "unranked", " -> ", "", 'Base Data'!EE9) | AF8: =IF(AND('Base Data'!EF9 <> "",'Base Data'!EF9 <> "?",'Base Data'!EF9 <> "---"), 'Base Data'!EF9, "")
B9: =IF(HomePage!C21 <> "", HomePage!B21, "") | C9: ='Base Data'!DW10 | D9: =IF(HomePage!C21 <> "", "vs", "") | E9: ='Base Data'!DP10 | F9: ='Base Data'!DQ10 | G9: ='Base Data'!DR10 | H9: ='Base Data'!DS10 | I9: ='Base Data'!DT10 | J9: ='Base Data'!DU10 | K9: ='Base Data'!DV10 | O9: ='Base Data'!CX10 | P9: ='Base Data'!CY10 | Q9: ='Base Data'!CV10 | R9: ='Base Data'!CW10 | T9: ='Base Data'!CZ10 | U9: ='Base Data'!DA10 | V9: ='Base Data'!DB10 | W9: ='Base Data'!DC10 | Z9: ='Base Data'!DE10 | AA9: ='Base Data'!DF10 | AB9: ='Base Data'!DG10 | AC9: ='Base Data'!DH10 | AD9: =IF('Base Data'!Y10 = "ots", "YES", "") | AE9: =SWITCH('Base Data'!EE10, "? -> ?", "pending", "--- -> ---", "unranked", " -> ", "", 'Base Data'!EE10) | AF9: =IF(AND('Base Data'!EF10 <> "",'Base Data'!EF10 <> "?",'Base Data'!EF10 <> "---"), 'Base Data'!EF10, "")
B10: =IF(HomePage!C22 <> "", HomePage!B22, "") | C10: ='Base Data'!DW11 | D10: =IF(HomePage!C22 <> "", "vs", "") | E10: ='Base Data'!DP11 | F10: ='Base Data'!DQ11 | G10: ='Base Data'!DR11 | H10: ='Base Data'!DS11 | I10: ='Base Data'!DT11 | J10: ='Base Data'!DU11 | K10: ='Base Data'!DV11 | O10: ='Base Data'!CX11 | P10: ='Base Data'!CY11 | Q10: ='Base Data'!CV11 | R10: ='Base Data'!CW11 | T10: ='Base Data'!CZ11 | U10: ='Base Data'!DA11 | V10: ='Base Data'!DB11 | W10: ='Base Data'!DC11 | Z10: ='Base Data'!DE11 | AA10: ='Base Data'!DF11 | AB10: ='Base Data'!DG11 | AC10: ='Base Data'!DH11 | AD10: =IF('Base Data'!Y11 = "ots", "YES", "") | AE10: =SWITCH('Base Data'!EE11, "? -> ?", "pending", "--- -> ---", "unranked", " -> ", "", 'Base Data'!EE11) | AF10: =IF(AND('Base Data'!EF11 <> "",'Base Data'!EF11 <> "?",'Base Data'!EF11 <> "---"), 'Base Data'!EF11, "")
B11: =IF(HomePage!C23 <> "", HomePage!B23, "") | C11: ='Base Data'!DW12 | D11: =IF(HomePage!C23 <> "", "vs", "") | E11: ='Base Data'!DP12 | F11: ='Base Data'!DQ12 | G11: ='Base Data'!DR12 | H11: ='Base Data'!DS12 | I11: ='Base Data'!DT12 | J11: ='Base Data'!DU12 | K11: ='Base Data'!DV12 | O11: ='Base Data'!CX12 | P11: ='Base Data'!CY12 | Q11: ='Base Data'!CV12 | R11: ='Base Data'!CW12 | T11: ='Base Data'!CZ12 | U11: ='Base Data'!DA12 | V11: ='Base Data'!DB12 | W11: ='Base Data'!DC12 | Z11: ='Base Data'!DE12 | AA11: ='Base Data'!DF12 | AB11: ='Base Data'!DG12 | AC11: ='Base Data'!DH12 | AD11: =IF('Base Data'!Y12 = "ots", "YES", "") | AE11: =SWITCH('Base Data'!EE12, "? -> ?", "pending", "--- -> ---", "unranked", " -> ", "", 'Base Data'!EE12) | AF11: =IF(AND('Base Data'!EF12 <> "",'Base Data'!EF12 <> "?",'Base Data'!EF12 <> "---"), 'Base Data'!EF12, "")
B12: =IF(HomePage!C24 <> "", HomePage!B24, "") | C12: ='Base Data'!DW13 | D12: =IF(HomePage!C24 <> "", "vs", "") | E12: ='Base Data'!DP13 | F12: ='Base Data'!DQ13 | G12: ='Base Data'!DR13 | H12: ='Base Data'!DS13 | I12: ='Base Data'!DT13 | J12: ='Base Data'!DU13 | K12: ='Base Data'!DV13 | O12: ='Base Data'!CX13 | P12: ='Base Data'!CY13 | Q12: ='Base Data'!CV13 | R12: ='Base Data'!CW13 | T12: ='Base Data'!CZ13 | U12: ='Base Data'!DA13 | V12: ='Base Data'!DB13 | W12: ='Base Data'!DC13 | Z12: ='Base Data'!DE13 | AA12: ='Base Data'!DF13 | AB12: ='Base Data'!DG13 | AC12: ='Base Data'!DH13 | AD12: =IF('Base Data'!Y13 = "ots", "YES", "") | AE12: =SWITCH('Base Data'!EE13, "? -> ?", "pending", "--- -> ---", "unranked", " -> ", "", 'Base Data'!EE13) | AF12: =IF(AND('Base Data'!EF13 <> "",'Base Data'!EF13 <> "?",'Base Data'!EF13 <> "---"), 'Base Data'!EF13, "")
B13: =IF(HomePage!C25 <> "", HomePage!B25, "") | C13: ='Base Data'!DW14 | D13: =IF(HomePage!C25 <> "", "vs", "") | E13: ='Base Data'!DP14 | F13: ='Base Data'!DQ14 | G13: ='Base Data'!DR14 | H13: ='Base Data'!DS14 | I13: ='Base Data'!DT14 | J13: ='Base Data'!DU14 | K13: ='Base Data'!DV14 | O13: ='Base Data'!CX14 | P13: ='Base Data'!CY14 | Q13: ='Base Data'!CV14 | R13: ='Base Data'!CW14 | T13: ='Base Data'!CZ14 | U13: ='Base Data'!DA14 | V13: ='Base Data'!DB14 | W13: ='Base Data'!DC14 | Z13: ='Base Data'!DE14 | AA13: ='Base Data'!DF14 | AB13: ='Base Data'!DG14 | AC13: ='Base Data'!DH14 | AD13: =IF('Base Data'!Y14 = "ots", "YES", "") | AE13: =SWITCH('Base Data'!EE14, "? -> ?", "pending", "--- -> ---", "unranked", " -> ", "", 'Base Data'!EE14) | AF13: =IF(AND('Base Data'!EF14 <> "",'Base Data'!EF14 <> "?",'Base Data'!EF14 <> "---"), 'Base Data'!EF14, "")
... B101: =IF(HomePage!C113 <> "", HomePage!B113, "") | C101: ='Base Data'!DW102 | D101: =IF(HomePage!C113 <> "", "vs", "") | E101: ='Base Data'!DP102 | F101: ='Base Data'!DQ102 | G101: ='Base Data'!DR102 | H101: ='Base Data'!DS102 | I101: ='Base Data'!DT102 | J101: ='Base Data'!DU102 | K101: ='Base Data'!DV102 | O101: ='Base Data'!CX102 | P101: ='Base Data'!CY102 | Q101: ='Base Data'!CV102 | R101: ='Base Data'!CW102 | T101: ='Base Data'!CZ102 | U101: ='Base Data'!DA102 | V101: ='Base Data'!DB102 | W101: ='Base Data'!DC102 | Z101: ='Base Data'!DE102 | AA101: ='Base Data'!DF102 | AB101: ='Base Data'!DG102 | AC101: ='Base Data'!DH102 | AD101: =IF('Base Data'!Y102 = "ots", "YES", "") | AE101: =SWITCH('Base Data'!EE102, "? -> ?", "pending", "--- -> ---", "unranked", " -> ", "", 'Base Data'!EE102) | AF101: =IF(AND('Base Data'!EF102 <> "",'Base Data'!EF102 <> "?",'Base Data'!EF102 <> "---"), 'Base Data'!EF102, "")

Sheet GBG Filtered
